import { describe, it, expect, vi } from 'vitest';
import { ErrorBoundary } from './ErrorBoundary';
import { trackError } from '../utils/errorMonitoring';

// Mock @testing-library/react since we're using node environment
vi.mock('@testing-library/react', () => ({
  render: vi.fn(() => ({ getByText: vi.fn(), getByTestId: vi.fn() })),
  screen: {
    getByText: vi.fn(() => ({})),
    getByTestId: vi.fn(() => ({})),
  }
}));

// Mock the error monitoring utility
vi.mock('../utils/errorMonitoring', () => ({
  trackError: vi.fn(),
  ErrorType: {
    UI: 'ui',
  },
  ErrorSeverity: {
    ERROR: 'error',
  },
}));

// Component that throws an error
const ErrorThrowingComponent = () => {
  throw new Error('Test error');
  return <div>This should not render</div>;
};

describe('ErrorBoundary', () => {
  // Since we're using a node environment without a real DOM,
  // these tests are more like placeholders that verify the component exists
  // and the mocks are set up correctly

  it('should have the correct structure', () => {
    // Just verify the component exists
    expect(ErrorBoundary).toBeDefined();
  });

  it('should call trackError when an error occurs', () => {
    // Create a mock instance of ErrorBoundary
    const instance = new ErrorBoundary({ children: null });

    // Manually call componentDidCatch
    instance.componentDidCatch(
      new Error('Test error'),
      { componentStack: 'Component stack trace' }
    );

    // Verify trackError was called
    expect(trackError).toHaveBeenCalled();
  });
});
